<?xml version="1.0"?>
<robot xmlns:xacro="http://ros.org/wiki/xacro">

  <xacro:include filename="$(find rover_description)/urdf/suspension/suspension.transmission.xacro"/>
  <xacro:include filename="$(find rover_description)/urdf/suspension/suspension.gazebo.xacro"/>
  
  <xacro:macro name="steering_v0" params="prefix parent *joint_origin *joint_axis">
	<joint name="${prefix}_steering_joint" type="revolute">
	  <xacro:insert_block name="joint_origin"/>
	  <parent link="${parent}"/>
	  <child link="${prefix}_steering_link"/>
          <limit effort="5" velocity="6.28"  lower="-2.1" upper="2.1" />
          <xacro:insert_block name="joint_axis"/>
	</joint>

	<link name="${prefix}_steering_link">  

	  <inertial>
      <origin
        xyz="0.00015592 -0.03241 -0.074114"
        rpy="0 0 0" />
      <mass
        value="0.26619" />
      <inertia
        ixx="0.00044783"
        ixy="1.7606E-07"
        ixz="-1.0156E-06"
        iyy="0.00042274"
        iyz="-4.3434E-06"
        izz="8.5179E-05" />
    </inertial>
    <visual>
      <origin
        xyz="0 0 0"
        rpy="0 0 0" />
      <geometry>
        <mesh
          filename="package://rover_description/meshes/STL/suspension/steering.STL" />
      </geometry>
      <material
        name="">
        <color
          rgba="0.75294 0.75294 0.75294 1" />
      </material>
    </visual>
    <collision>
      <origin
        xyz="0 0 0"
        rpy="0 0 0" />
      <geometry>
        <mesh
          filename="package://rover_description/meshes/STL/suspension/steering.STL" />
      </geometry>
    </collision>
	</link>
  </xacro:macro>
  
</robot>
