<?xml version="1.0"?>
<robot xmlns:xacro="http://ros.org/wiki/xacro">

  <xacro:include filename="$(find rover_description)/urdf/wheel/wheel.transmission.xacro"/>
  <xacro:include filename="$(find rover_description)/urdf/wheel/wheel.gazebo.xacro"/>
  
  <xacro:macro name="wheel_v0" params="prefix parent *joint_origin *joint_axis">
	<joint name="${prefix}_wheel_joint" type="continuous">
	  <xacro:insert_block name="joint_origin"/>
	  <parent link="${parent}"/>
	  <child link="${prefix}_wheel_link"/>
         <limit effort="1.5" velocity="20"/>
	  <xacro:insert_block name="joint_axis"/>
	</joint>

	<link name="${prefix}_wheel_link">
	  <inertial>
      <origin
        xyz="5.9053E-07 -0.0064734 -1.1775E-07"
        rpy="0 0 0" />
      <mass
        value="0.63096" />
      <inertia
        ixx="0.0015238"
        ixy="1.7127E-09"
        ixz="-6.387E-10"
        iyy="0.0029312"
        iyz="-3.3048E-09"
        izz="0.0015238" />
    </inertial>
    <visual>
      <origin
        xyz="0 0 0"
        rpy="0 0 0" />
      <geometry>
        <mesh
          filename="package://rover_description/meshes/STL/wheel/wheel.STL" />
      </geometry>
      <material
        name="">
        <color
          rgba="0.25098 0.25098 0.25098 1" />
      </material>
    </visual>
    <collision>
      <origin
        xyz="0 0 0"
        rpy="0 0 0" />
      <geometry>
        <mesh
          filename="package://rover_description/meshes/STL/wheel/wheel.STL" />
      </geometry>
    </collision>
	</link>
  </xacro:macro>
  
</robot>

