<?xml version="1.0"?>
<robot xmlns:xacro="http://ros.org/wiki/xacro">

  <xacro:include filename="$(find rover_description)/urdf/wheel/wheel.transmission.xacro"/>
  <xacro:include filename="$(find rover_description)/urdf/wheel/wheel.gazebo.xacro"/>
  
  <xacro:macro name="wheel_v0" params="prefix parent *joint_origin *joint_axis">
	<joint name="${prefix}_wheel_joint" type="continuous">
	  <xacro:insert_block name="joint_origin"/>
	  <parent link="${parent}"/>
	  <child link="${prefix}_wheel_link"/>
         <limit effort="1.5" velocity="20"/>
	  <xacro:insert_block name="joint_axis"/>
	</joint>

	<link name="${prefix}_wheel_link">
	  <inertial>
      <origin
        xyz="0.0019728 -0.00016049 2.625E-06"
        rpy="0 0 0" />
      <mass
        value="0.24321" />
      <inertia
        ixx="0.00082645"
        ixy="-2.6396E-05"
        ixz="6.9353E-10"
        iyy="0.00052575"
        iyz="6.4571E-09"
        izz="0.00052343" />
    </inertial>
    <visual>
      <origin
        xyz="0 0 0"
        rpy="0 0 0" />
      <geometry>
        <mesh
          filename="package://rover_description/meshes/STL/wheel/robot_wheel.stl" />
      </geometry>
      <material
        name="">
        <color
          rgba="0.25098 0.25098 0.25098 1" />
      </material>
    </visual>
    <collision>
      <origin
        xyz="0 0 0"
        rpy="0 0 0" />
      <geometry>
        <mesh
          filename="package://rover_description/meshes/STL/wheel/robot_wheel.stl" />
      </geometry>
    </collision>
	</link>
  </xacro:macro>
  
</robot>

